Workbook

Sheet S1 - Interventions
A1: Supplementary File S1. Extracted data from interventions years 2000-2025
A2: Notes: Papers are grouped by the review which they were mentioned in. If a paper was mentioned in more than one review it has only been included once.
A3: Papers in these subsection were then grouped based on efficacy; Column E: "Effective", "Not effective" and "All groups improved".
A4: Where interventions led to comparable improvements in both the intervention and control groups, they were coded as "All groups improved".
A5: For age, reasonable assumptions/calculations were made to impute missing additional data for higher-powered downstream analyses (see individual cells for exact calculations; where there is no calculation, the mean was provided in the paper).
A6: In terms of behaviour change techniques (BCTs) (column 'AC'), all interventions used the domain ‘BCIO:007017: monitoring’ as in 'BCIO:007026: provide biofeedback', so this was not specified in the datasheet. Where monitoring was specified, it was an additional monitoring BCT (i.e self-monitoring results through an app).
A7: BCTs for Celis-Morales et al. 2017; Livingstone et al. 2016 and Damschroder et al. 2020 were coded from their respective protocol papers, published separately (DOIs: 10.1007/s12263-014-0450-2 and 10.2196/12526).
A9: Authors | B9: Title | C9: Year | D9: DOI | E9: Effective? | F9: Behaviour | G9: Number of target behaviours | H9: Grouped biofeedback markers | I9: Biofeedback markers | J9: Specific biofeedback markers | K9: Number of biofeedback markers | L9: Study design | M9: Population | N9: Number of participants | O9: Proportion female | P9: Mean age | Q9: Income identified? | R9: Education identified? | S9: Intervention period | T9: Intervention design | U9: Education/counselling | V9: Measured outcome(s) | W9: BC primary outcome? | X9: Reported results | Y9: Measured post-intervention maintenance? | Z9: Communication mode | AA9: Number of modes of communication | AB9: Frequency of feedback | AC9: Behaviour Change Theory | AD9: Behaviour Change Techniques [DOMAIN LEVEL] | AE9: Number of BCTs used | AF9: BCT for monitoring specifically (non-biomarker)?
A10: Papers from Richardson et al., 2023 DOI:10.2196/44359
A11: Babazono, A., Kame, C., Ishihara, R., Yamamoto, E., Hillman, A. L. | B11: Patient-motivated prevention of lifestyle-related disease in Japan: a randomized, controlled clinical trial | C11: 2007 | D11: 10.2165/00115677-200715020-00007 | E11: Effective | F11: Alcohol reduction, Diet, Physical activity | G11: 3 | H11: {=_xlfn.TEXTJOIN(", ", TRUE, IF(OR(ISNUMBER(SEARCH({"blood pressure","heart rate","anthropometrics","ecg","vo2max","spirometry","respiratory rate"},I11))),"Physiological", ""), IF(OR(ISNUMBER(SEARCH({"genetic"},I11))),"Risk", ""), IF(OR(ISNUMBER(SEARCH({"ultrasound","uv photog","facial","oral","CT scan"},I11))),"Imaging", ""), IF(OR(ISNUMBER(SEARCH({"glucose","hb1ac","lipids","nutrient"},I11))),"Blood", ""),IF(OR(ISNUMBER(SEARCH({"anthropometrics"},I11))),"Anthropometry", ""))} -> Physiological, Blood, Anthropometry | I11: Blood pressure, HbA1c, lipids, anthropometrics | J11: Blood pressure, HbA1c, lipids, weight/BMI | K11: 4 | L11: Randomised intervention | M11: General practice patients referred by GP for program, study included people with stage 1 hypertension or elevated hbA1c | N11: 87 | O11: 58.6 | P11: 64.4 | Q11: No | R11: No | S11: 12 months | T11: Patients were randomised into either the Health Promotion Program (HPP) or control groups. All patients had biomarker testing at baseline, 4, 6 and 12 months. The intervention group were encouraged to set goals and select their own lifestyle improvements with the support of dietitians, exercise instructors and nurses. Home-visits were made twice per year for follow up and support. The control group received their health results and general printed information about exercise only. | U11: Yes | V11: Primary outcomes included changes in vegetable intake and PA levels (steps per day). Secondary measures included bodyweight, BMI, BP, blood lipids, HbA1c, and a general health questionanaire (GHQ30). | W11: Yes | X11: Intervention group significantly increased their mean steps per day (from 7,345 to 10,373, p.<0.001). Control group did not. The difference in steps between intervention and control was statistically significant. After a year, the proportion of patients consuming ≥2 meals with servings of any type of vegetable per day was 85% (up from 73.9%), and the control group was 73.2% (up from 70.7%). Intervention group participants were more likely to consume ≥2 meals with any type of vegetable than the control group (OR 3.8; 95%CI 1.0-14.0, p<0.05). Consumption of green/yellow vegetables also increased among intervention participants, with 50% (up from 34.8%) consuming ≥2 meals with green/yellow yegetables. This did not change in control group participants. Thus, the intervention group members were more likely to consume ≥2 meals with green/yellow vegetables (OR 4.2, 95%CI 1.4-12.6, p<0.05). There were no statistically significant changes in body weight, BMI, BP, cholesterol, TGs, HbA1c or GHQ30. | Y11: No | Z11: In person | AA11: 1 | AB11: Once | AC11: Health Belief Model, Transtheoretical Model | AD11: Goal directed BCT Social support BCT | AE11: 2
A12: Almeida, V., Littlejohn, P., Cop, I., Brown, E., Afroze, R., Davison, K. M. | B12: Comparison of Nutrigenomics Technology Interface Tools for Consumers and Health Professionals: A Sequential Explanatory Mixed Methods Investigation | C12: 2019 | D12: 10.2196/12580 | E12: Effective | F12: Diet | G12: 1 | H12: {=_xlfn.TEXTJOIN(", ", TRUE, IF(OR(ISNUMBER(SEARCH({"blood pressure","heart rate","anthropometrics","ecg","vo2max","spirometry","respiratory rate"},I12))),"Physiological", ""), IF(OR(ISNUMBER(SEARCH({"genetic"},I12))),"Risk", ""), IF(OR(ISNUMBER(SEARCH({"ultrasound","uv photog","facial","oral","CT scan"},I12))),"Imaging", ""), IF(OR(ISNUMBER(SEARCH({"glucose","hb1ac","lipids","nutrient"},I12))),"Blood", ""),IF(OR(ISNUMBER(SEARCH({"anthropometrics"},I12))),"Anthropometry", ""))} -> Risk | I12: Genetics | J12: Genetics | K12: 1 | L12: RCT | M12: Adults aged 37-57 years (mean age 45.8 years, SD 5.8). | N12: 55 | O12: 74.6 | P12: 45.8 | Q12: Yes | R12: Yes | S12: 9 weeks | T12: Participants were randomised to receive a standard nutrition-based gene test report (control; n=19) or a practitioner-facilitated personalised nutrition intervention (intervention; n=36). | U12: Yes | V12: Primary: Differences in the diet quality score (Healthy Eating Index–Canadian [HEI-C]; proportion [%] of calories from total fat, saturated fat, and sugar; omega 3 fatty acid intake [grams]; sodium intake [milligrams]); as well as health-related quality of life (HRQoL) scale score. Secondary: Anthropometrics, self-efficacy. | W12: Yes | X12: Percentage of calories from total fat (mean difference [MD]=−5.1%; Wilks’ lambda [λ]=0.817; F1,53= 11.68; P=.001; eta-squared [η²]=0.183 ) as well as from saturated fat (MD=−1.7%; λ=0.816; F1,53=11.71; P=.001; η²=0.18) and health-related quality of life (HRQoL) scores (MD=8.1 points; λ=0.914; F1,53=4.92; P=.03; η²=0.086). There were significant differences between groups over time for sodium (λ=0.846; F1,53=9.47; P=.003; η²=0.15) and HEI-C scores (λ=0.660; F1,53=27.43; P<.001; η²=0.35. | Y12: No | Z12: In person | AA12: 1 | AB12: Once | AC12: Transtheoretical Model | AD12: Goal directed BCT | AE12: 1
A13: Celis-Morales, C., Livingstone, K. M., Marsaux, C. F., Macready, A. L., Fallaize, R., O'Donovan, C. B., Woolhead, C., Forster, H., Walsh, M. C., Navas-Carretero, S., San-Cristobal, R., Tsirigoti, L., Lambrinou, C. P., Mavrogianni, C., Moschonis, G., Kolossa, S., Hallmann, J., Godlewska, M., Surwillo, A., Traczyk, I., Drevon, C. A., Bouwman, J., van Ommen, B., Grimaldi, K., Parnell, L. D., Matthews, J. N., Manios, Y., Daniel, H., Martinez, J. A., Lovegrove, J. A., Gibney, E. R., Brennan, L., Saris, W. H., Gibney, M., Mathers, J. C., Food4Me, Study | B13: Effect of personalized nutrition on health-related behaviour change: evidence from the Food4Me European randomized controlled trial | C13: 2017 | D13: 10.1093/ije/dyw186 | E13: Effective | F13: Diet | G13: 1 | H13: {=_xlfn.TEXTJOIN(", ", TRUE, IF(OR(ISNUMBER(SEARCH({"blood pressure","heart rate","anthropometrics","ecg","vo2max","spirometry","respiratory rate"},I13))),"Physiological", ""), IF(OR(ISNUMBER(SEARCH({"genetic"},I13))),"Risk", ""), IF(OR(ISNUMBER(SEARCH({"ultrasound","uv photog","facial","oral","CT scan"},I13))),"Imaging", ""), IF(OR(ISNUMBER(SEARCH({"glucose","hb1ac","lipids","nutrient"},I13))),"Blood", ""),IF(OR(ISNUMBER(SEARCH({"anthropometrics"},I13))),"Anthropometry", ""))} -> Physiological, Risk, Blood, Anthropometry | I13: Genetics, glucose, lipids, nutrient biomarkers, anthropometrics | J13: Genetics, weight/BMI, blood glucose, total cholesterol, carotenoids, omega-3 fatty acid index and 32 other fatty acids, and vitamin D | K13: 5 | L13: RCT | M13: Adults. | N13: 1488 | O13: 59 | P13: 39.8 | Q13: No | R13: No | S13: 6 months | T13: Four-arm intervention: Control group/Level 0 (L0): non-personalised dietary, body weight and physical activity (PA) advice based on population guidelines; Level 1 (L1): personalised nutrition (PN) advice based on individual dietary intake data alone; Level 2 (L2): PN advice based on individual dietary intake and phenotypic data; Level 3 (L3): PN advice based on individual dietary intake and phenotypic and genotypic data. | U13: No | V13: Primary: Changes to dietary intake. Secondary: anthropometric measures (body weight (BW), body mass index (BMI) and waist circumference) and blood biomarkers (total cholesterol (TC), carotenoids and fatty acids). | W13: Yes | X13: All participants improved their diet over the intervention period. Individuals receiving PN advice consumed less red meat (8.5%), salt (6.3%), and energy (4.4%), and had higher healthy eating index (HEI) scores (2.6%) compared with the Control group. No significant differences were seen in the other food groups. Changes in dietary outcomes did not differ between Levels 1, 2 and 3 of PN. Nutrient changes were assessed in salt, saturated fat, dietary fibre, folate and polyunsaturated fatty acids (PUFAs). Participants receiving PN advice consumed less salt (8.9%) and saturated fat (7.8%) and had higher folate intake (11.5%) compared with controls. No significant changes to biomarkers or anthropometric measures at conclusion of the intervention. | Y13: No | Z13: Written Communication | AA13: 1 | AB13: Once | AC13: None | AD13: Monitoring BCT Increase awareness of consequences BCT Social Support | AE13: 3 | AF13: BCIO:007019: record behaviour without feedback BCT **NOTE: from BCTO hierarchy sheet The monitoring agent can be a human or a technical device. If recording is part of a data collection procedure rather than a strategy aimed at changing behaviour, do not code; if feedback given, code only 'provide feedback on outcome of behaviour BCT' and not this class; if observing behaviour code 'observe behaviour without feedback BCT'.
A14: Nielsen, D. E., El-Sohemy, A. | B14: Disclosure of genetic information and change in dietary intake: a randomized controlled trial | C14: 2014 | D14: 10.1371/journal.pone.0112665 | E14: Effective | F14: Diet | G14: 1 | H14: {=_xlfn.TEXTJOIN(", ", TRUE, IF(OR(ISNUMBER(SEARCH({"blood pressure","heart rate","anthropometrics","ecg","vo2max","spirometry","respiratory rate"},I14))),"Physiological", ""), IF(OR(ISNUMBER(SEARCH({"genetic"},I14))),"Risk", ""), IF(OR(ISNUMBER(SEARCH({"ultrasound","uv photog","facial","oral","CT scan"},I14))),"Imaging", ""), IF(OR(ISNUMBER(SEARCH({"glucose","hb1ac","lipids","nutrient"},I14))),"Blood", ""),IF(OR(ISNUMBER(SEARCH({"anthropometrics"},I14))),"Anthropometry", ""))} -> Risk | I14: Genetics | J14: SNPs that affect caffeine metabolism (CYP1A2), vitamin C utilisation (GSTT1 and GSTM1), sweet taste perception (TAS1R2), and sodium-sensitivity (ACE) | K14: 1 | L14: double-blinded, parallel group RCT | M14: Healthy adults (age 26.5+/-3.0 years) | N14: 138 | O14: 78 | P14: 26.5 | Q14: No | R14: Yes | S14: 12 months | T14: Intended to mimic the nature of a direct to-consumer genetic test: all study materials were distributed and completed via mail/electronically. No in-person contact was made with subjects. Subjects who had previously participated in a nutrigenomics research study and had provided a blood sample were invited to complete a 196-item, semi-quantitative Toronto modified Willet food frequency questionnaire (FFQ) and were then randomized to an intervention or control group (2:1 ratio). The intervention group consisted of those who would have either the ‘‘risk’’ or ‘‘non-risk’’ genotype for each of the genes. The dietary report for subjects in the intervention group informed subjects of their genotypes and included a corresponding DNA-based dietary recommendation for daily intake of caffeine, vitamin C, added sugars and sodium. Those who possessed the genotype that has been associated with increased risk of a health outcome when consuming above or below a certain daily amount were given a ‘‘targeted’’ dietary recommendation. For caffeine and sodium, this recommendation was more stringent than the current general recommendation for daily intake, based on previous research that evaluated health outcomes according to genotype at different levels of intake. For added sugars and vitamin C, subjects were to meet the current general recommendation for daily intake, since no previous study has examined how individuals respond to consuming various levels of these nutrients according to genotype. Subjects who possessed the genotype that has not been associated with increased risk received the current general recommendation for daily intake. The control group was e-mailed a report of current general recommendations for the same nutrients without genetic information. Subjects were e-mailed a monthly reminder of their dietary report and additional FFQs were collected at 3- and 12-month follow-up assessments. | U14: No | V14: Primary outcome: change in dietary intakes of caffeine, vitamin C, added sugars, and sodium between the control and intervention groups from baseline to the follow-up assessments. Changes in dietary intakes between baseline and 3-months determined short-term effects of the intervention, while changes in intakes between baseline and 12- months were considered long-term effects. Secondary outcome: the proportion of participants who met recommendations for intake before/after the intervention for dietary components that significantly changed between the control and intervention groups. | W14: Yes | X14: No significant changes from baseline for intakes of caffeine, vitamin C, added sugars, or sodium at the 3-month follow-up among subjects in the intervention risk group, nor among subjects in the intervention non-risk group (Compared to the control group). At 12-month follow-up, intervention risk group subjects who possessed the risk version of the ACE gene (thus given the targeted advice to consume below the Adequate Intake [AI] of 1500 mg/day of sodium), significantly reduced their mean sodium intake (mg/day) from baseline when compared to the control group (-287.3 ±114.1 vs. 129.8 ±118.2, p = 0.008) (control group was given the general recommendation for sodium intake [Tolerable Upper Intake Level (UL): ≤2300 mg/day]). The mean change in sodium intake (mg/day) among non-risk intervention subjects for the the ACE gene (advised to follow the general recommendation for sodium intake), did not differ from the change in intake of the control group at 12-months. Among those in the risk intervention group for the ACE gene, 19% met the targeted recommendation of ≤1500 mg/day at baseline compared to 34% after 12 months (p = 0.06), and 59% met the general recommendation of ≤2300 mg/day at baseline compared to 66% after 12 months (p = 0.41). The mean changes in intakes from baseline for caffeine, vitamin C and added sugars did not differ from the control group at the 12-month follow-up among either the intervention-risk or intervention non-risk group. | Y14: No | Z14: Written Communication | AA14: 1 | AB14: Once | AC14: None | AD14: Increase awareness of consequences BCT Guide to how to perform behaviour BCT | AE14: 2
A15: Williams, D. R., Lewis, N. M. | B15: Effectiveness of nutrition counseling in young adult males | C15: 2002 | D15: 10.1016/S0271-5317(02)00399-8 | E15: Effective | F15: Diet | G15: 1 | H15: {=_xlfn.TEXTJOIN(", ", TRUE, IF(OR(ISNUMBER(SEARCH({"blood pressure","heart rate","anthropometrics","ecg","vo2max","spirometry","respiratory rate"},I15))),"Physiological", ""), IF(OR(ISNUMBER(SEARCH({"genetic"},I15))),"Risk", ""), IF(OR(ISNUMBER(SEARCH({"ultrasound","uv photog","facial","oral","CT scan"},I15))),"Imaging", ""), IF(OR(ISNUMBER(SEARCH({"glucose","hb1ac","lipids","nutrient"},I15))),"Blood", ""),IF(OR(ISNUMBER(SEARCH({"anthropometrics"},I15))),"Anthropometry", ""))} -> Blood | I15: Lipids | J15: Cholesterol | K15: 1 | L15: Randomised trial | M15: Healthy males (aged 21.5 +/- 1.4 years) | N15: 45 | O15: 0 | P15: 21.5 | Q15: No | R15: No | S15: 6 weeks | T15: Men were randomly assigned to one of four groups; nutrition counselling and measurement of serum cholesterol (NC + SC), nutrition counselling only (NC), measurement of serum cholesterol only (SC), or control (C). At weeks 1 and 6, participants completed a 24-hour recall, a 2-day food record, and a food frequency questionnaire. The groups who recieved nutrition counselling were presented with a computer nutrient analysis of their food intake to help them identify sources of fat in their diet. | U15: Yes | V15: Dietary changes, fat intake (% of E), perception of nutrition counselling | W15: Yes | X15: In the NC + SC group there was a significant reduction in fat (-3.2 ±1.4, P 0.02) from pre- to post-intervention, the NC, SC and C groups did not experience a significant change in percent calories from fat. Participants who received nutrition counseling (NC + SC and NC groups) increased their servings of fresh fruit, “light” salad dressing, and <30% fat ground beef after the counseling (P 0.05). There were no differences in the food frequency from pre- to post-assessment in the SC and C groups. All of the men who received nutrition counselling reported gaining some nutrition knowledge by their participation in this study and 92% said that the nutrition counselling convinced them that lowering their dietary fat intake would reduce their risk of CHD. 96% of the participants stated they had made dietary changes as a result of the study, such as "eating less fast food" and "eating more fruits and vegetables". A small subgroup (31%) of the participants responded negatively to goal setting. 92% said seeing a model of the “clogged artery” in a nutrition counselling session was helpful. | Y15: No | Z15: In person | AA15: 1 | AB15: Once | AC15: None | AD15: Goal directed BCT Increase awareness of consequences BCT | AE15: 2
A16: Livingstone, K. M., Celis-Morales, C., Navas-Carretero, S., San-Cristobal, R., Macready, A. L., Fallaize, R., Forster, H., Woolhead, C., O'Donovan, C. B., Marsaux, C. F., Kolossa, S., Tsirigoti, L., Lambrinou, C. P., Moschonis, G., Godlewska, M., Surwillo, A., Drevon, C. A., Manios, Y., Traczyk, I., Gibney, E. R., Brennan, L., Walsh, M. C., Lovegrove, J. A., Saris, W. H., Daniel, H., Gibney, M., Martinez, J. A., Mathers, J. C., Food4Me, Study | B16: Effect of an Internet-based, personalized nutrition randomized trial on dietary changes associated with the Mediterranean diet: the Food4Me Study | C16: 2016 | D16: 10.3945/ajcn.115.129049 | E16: Effective | F16: Diet, Physical activity | G16: 2 | H16: {=_xlfn.TEXTJOIN(", ", TRUE, IF(OR(ISNUMBER(SEARCH({"blood pressure","heart rate","anthropometrics","ecg","vo2max","spirometry","respiratory rate"},I16))),"Physiological", ""), IF(OR(ISNUMBER(SEARCH({"genetic"},I16))),"Risk", ""), IF(OR(ISNUMBER(SEARCH({"ultrasound","uv photog","facial","oral","CT scan"},I16))),"Imaging", ""), IF(OR(ISNUMBER(SEARCH({"glucose","hb1ac","lipids","nutrient"},I16))),"Blood", ""),IF(OR(ISNUMBER(SEARCH({"anthropometrics"},I16))),"Anthropometry", ""))} -> Physiological, Risk, Blood, Anthropometry | I16: Genetics, lipids, nutrient biomarkers, anthropometrics | J16: Genetics, glucose, lipids, nutrient biomarkers, weight/BMI | K16: 4 | L16: RCT | M16: Adults (aged 39.9 ± 13.0 years). | N16: 1270 | O16: 59 | P16: 39.9 | Q16: Unclear | R16: Unclear | S16: 6 months | T16: 6-month, four-arm intervention. Control group/Level 0 (L0): non-personalised dietary, body weight and physical activity (PA) advice based on population guidelines; Level 1 (L1): personalised nutrition (PN) advice based on individual dietary intake data alone; Level 2 (L2): PN advice based on individual dietary intake and phenotypic data; Level 3 (L3): PN advice based on individual dietary intake and phenotypic and genotypic data. | U16: No | V16: Changes to dietary consumption as measured by MedDiet scores. | W16: Yes | X16: MedDiet scores were greater in individuals randomly assigned to PN (mean L1, L2 and L3) than in controls (L0) (PN compared with control arms: 5.20 ± 0.05 and 5.48 ± 0.07, respectively; P = 0.002). MedDiet scores at month 6 in participants who received PN advice on the basis of current diet alone (L1) were not significantly different from those randomly assigned to L2 and L3 [who received advice on the basis of current diet + phenotype (L2) and diet + phenotype + genotype (L3)]. However, MedDiet scores at month 6 for participants who received PN advice in L3 (diet + phenotype + genotype) were greater than in participants in L2 at month 6 (L3 compared with L2: 5.63 ± 0.10 and 5.38 ± 0.10, respectively; P = 0.029). | Y16: No | Z16: Written Communication | AA16: 1 | AB16: Once | AC16: Protection Motivation Theory | AD16: Social support BCT Monitoring BCT Increase awareness of consequences BCT Goal directed BCT | AE16: 4 | AF16: BCIO:007019: record behaviour without feedback BCT **NOTE: from BCTO hierarchy sheet The monitoring agent can be a human or a technical device. If recording is part of a data collection procedure rather than a strategy aimed at changing behaviour, do not code; if feedback given, code only 'provide feedback on outcome of behaviour BCT' and not this class; if observing behaviour code 'observe behaviour without feedback BCT'.
A17: Olson, R., Thompson, S. V., Elliot, D. L., Hess, J. A., Rhoten, K. L., Parker, K. N., Wright, R. R., Wipfli, B., Bettencourt, K. M., Buckmaster, A., Marino, M. | B17: Safety and Health Support for Home Care Workers: The COMPASS Randomized Controlled Trial | C17: 2016 | D17: 10.2105/AJPH.2016.303327 | E17: Effective | F17: Diet, Physical activity, workplace safety behaviours | G17: 2 | H17: {=_xlfn.TEXTJOIN(", ", TRUE, IF(OR(ISNUMBER(SEARCH({"blood pressure","heart rate","anthropometrics","ecg","vo2max","spirometry","respiratory rate"},I17))),"Physiological", ""), IF(OR(ISNUMBER(SEARCH({"genetic"},I17))),"Risk", ""), IF(OR(ISNUMBER(SEARCH({"ultrasound","uv photog","facial","oral","CT scan"},I17))),"Imaging", ""), IF(OR(ISNUMBER(SEARCH({"glucose","hb1ac","lipids","nutrient"},I17))),"Blood", ""),IF(OR(ISNUMBER(SEARCH({"anthropometrics"},I17))),"Anthropometry", ""))} -> Physiological, Blood, Anthropometry | I17: Blood pressure, glucose, lipids, anthropometrics | J17: Blood pressure, glucose, lipids, weight/BMI | K17: 4 | L17: RCT | M17: Healthcare workers (aged 51.6 years, SD=13.2) | N17: 149 | O17: 89 | P17: 51.6 | Q17: No | R17: No | S17: 12 months | T17: Clusters of healthcare workers were filled with workers who had similar availability and location of residences (total of 16 clusters with a range of 7–12 members totalling n=74 intervention; n=74 usual practice), plus an additional intervention participant did not complete baseline but completed subsequent assessments. Once 2 clusters were filled, one was randomized to intervention and the other to usual practice control. After baseline data collection, all participants received immediate feedback on physical measurements relative to normal or healthy standards and were informed of their random assignment. Control participants received pay and materials (compensation for time) and concluded enrollment. The control participants had access to the usual resources provided by their union/s, therefore, it was possible for control participants to attend monthly paid training that matched or exceeded total paid monthly activities for intervention participants. Intervention participants received a brief intervention orientation and additional materials (workbook, knee pad, step counter) before finishing enrollment. The intervention clusters participated in a researcher-led half-day workshop followed by 12 monthly peer-led meetings that were implemented by using scripted workbooks and supporting materials. Team leader recieved additional instructions and brief facilitator training at the beginning and midway through the program. Monthly meetings involved a WorkLife check-in (i.e., rating or sharing current work and life status), educational lesson, goal setting, healthy meal break, WorkLife support (i.e., structured problem solving), and a reflection. Educational lessons and goals alternated between safety and health or well-being topics. COMPASS workbook 1, which was developed and revised on the basis of a pilot study, was used during the first 6 months. Workbook 2, which was developed and tested with a subgroup of original pilot participants, was used during months 7 through 12. Instead of fully scripted lessons, workbook 2 allowed teams to choose a schedule of readings from a menu of options. Each “reading discussion” option included scripted group and individual goal setting. Intervention participants were provided individual and team “certification” incentives for meeting certain attendance and goal completion criteria. | U17: Yes | V17: Primary outcomes: Community of practice (i.e., people engaged in a common activity who interact regularly for shared learning and improvement). Well-being was measured with the 12-item Short Form Health Survey version 2.0; health behaviours including daily fruit and vegetable consumption (via the National Cancer Institute fruit and vegetable screener), reduced daily consumption of high-fat and high-sugar foods (questions about frequency of consuming sugary drinks, sugary snacks, and fast food, and bringing meals from home) PA scale (5 d/wk with 30 minutes of moderate exercise), and safe behaviors and conditions when working in clients' homes (assessed with questionnaire about frequency of specific actions in the past 6 months). Secondary outcomes: Sleep quality (assessed using a single item from the Pittsburgh Sleep Quality Index), Psychosocial experiences and stress measures. An adapted Nordic questionnaire assessed the degree to which musculoskeletal pain and discomfort interfered with normal tasks, functional impairment with activities of daily living, work related injuries, and lost work time attributable to illness or injury. Physiological measures included blood pressure, blood lipids and glucose,BMI, grip strength, hamstring flexibility (using a Sit and Reach box), and a 6-minute walk test. | W17: Yes | X17: Statistically significant and sustained improvement in experienced community of practice (6-month effect size (d) =0.36; P=.023; 12-month d=0.37; P.024); talking with CEs about improving unsafe conditions (12-month d=0.84; P<.001); correcting slip, trip, or fall hazards (12-month d=0.45; P=.027); using new tools or techniques for moving objects or CEs (6-month d=0.65, P=.009); using new tools or techniques for house cleaning (6-month d=0.51; P=.041; 12-month d=0.64; P=.006); and daily fruit and vegetable servings (12-month d=0.31; P=.038). Interestingly, among intervention participants there was a a significant reduction in meals brought from home relative to controls (12-month d=−0.46; P=.014). Longitudinal between-group contrasts for other secondary outcomes included significant improvements in high-density lipoprotein (6-month d=0.22; P=.045) and grip strength (12-month d=0.29; P=.011), as well as a significant reduction in lost work days because of injury (6-month d=−0.66; P=.01). Remaining secondary outcomes among HCWs were predominantly stable and nonsignificant. According to Cohen’s standards for small (d = 0.20), moderate (d = 0.50), and large (d = 0.80) effect sizes, effects for fruit and vegetable consumption and community of practice and were small to moderate, while effect sizes for safety behaviors ranged from moderate to large. | Y17: No | Z17: In person | AA17: 1 | AB17: Once | AC17: None | AD17: Goal directed BCT Social support BCT Monitoring BCT Advise specific behaviour BCT | AE17: 4 | AF17: BCT2.3 Self-monitoring of behaviour
A18: Greene, J., Sacks, R., Piniewski, B., Kil, D., Hahn, J. S. | B18: The impact of an online social network with wireless monitoring devices on physical activity and weight loss | C18: 2013 | D18: 10.1177/2150131912469546 | E18: Effective | F18: Diet, Physical activity | G18: 2 | H18: {=_xlfn.TEXTJOIN(", ", TRUE, IF(OR(ISNUMBER(SEARCH({"blood pressure","heart rate","anthropometrics","ecg","vo2max","spirometry","respiratory rate"},I18))),"Physiological", ""), IF(OR(ISNUMBER(SEARCH({"genetic"},I18))),"Risk", ""), IF(OR(ISNUMBER(SEARCH({"ultrasound","uv photog","facial","oral","CT scan"},I18))),"Imaging", ""), IF(OR(ISNUMBER(SEARCH({"glucose","hb1ac","lipids","nutrient"},I18))),"Blood", ""),IF(OR(ISNUMBER(SEARCH({"anthropometrics"},I18))),"Anthropometry", ""))} -> Physiological, Anthropometry | I18: Anthropometrics | J18: Weight/BMI | K18: 1 | L18: randomised intervention | M18: Adults (most [60%] 50+ years). Age reported as buckets; midpoints of buckets assumed for definite ranges (e.g., "40-49 years" = 44.5 years), while indefinite ranges (age < 40 and age > 60) are estimated as the next nearest 10 (i.e., 30 and 70) as overall ages are 18-79. | N18: 349 | O18: 78.9 | P18: =(30*21.7+44.5*17.9+54.5*42.8+70*17.6)/100 -> 50.1215 | Q18: No | R18: No | S18: 6 months | T18: Participants were randomly assigned to intervention or control groups. All participants received printed guidelines on diet and exercise during their first study visit. Materials included a sample daily meal plan with recommended serving sizes, a handout about recommended daily levels of exercise, and articles about the benefits of exercise and healthy eating. Intervention participants were provided access to the iWell OSN and were given an accelerometer that allowed them to capture PA/step count for upload to the iWell OSN and a wireless weight scale for uploading weight data. With the iWell OSN, participants could connect (“friend”) others in the network, send individual messages to their friends, make public postings, view their contact’s postings, view their PA/steps, view their weight, and compete against others in the network on step count. The iWell OSN also allowed participants to set health-related goals and to receive motivational messages. | U18: No | V18: Physical activity levels, weight, Blood lipids. | W18: Yes | X18: The intervention group significantly increased weekly leisure walking from 129 to 341 minutes, on average, a 164% increase over the 6-month study period, compared with a 47% increase for the control group. The intervention group had larger (non-significant) increases in 9 other areas of PA compared to the control group. The intervention group also lost more weight over the 6-month study period than did the control group (mean 5.2 vs 1.6 pounds). No significant differences between intervention and control for change in LDL-c and HDL-c levels. The intervention group had a significant reduction in triglycerides at 3 months compared with the control group, but it was not sustained at 6 months. In multivariate regressions, the number of messages sent by participants was positively related to increases in leisure time walking minutes and it was negatively related to weight change. In other words, the more messages a participant sent on the iWell OSN, the more likely they increased the number of minutes walked, and reduced their weight. | Y18: No | Z18: Device/Online | AA18: 1 | AB18: More than once | AC18: None | AD18: Social support BCT Goal directed BCT Guide how to perform behaviour BCT Monitoring BCT | AE18: 4 | AF18: BCT2.3 Self-monitoring of behaviour BCT2.4 Self-monitoring of outcome(s) of behaviour
A19: Schopp, L. H., Clark, M. J., Lamberson, W. R., Uhr, D. J., Minor, M. A. | B19: A randomized controlled trial to evaluate outcomes of a workplace self-management intervention and an intensive monitoring intervention | C19: 2017 | D19: 10.1093/her/cyx042 | E19: Effective | F19: Diet, Physical activity, stress management | G19: 3 | H19: {=_xlfn.TEXTJOIN(", ", TRUE, IF(OR(ISNUMBER(SEARCH({"blood pressure","heart rate","anthropometrics","ecg","vo2max","spirometry","respiratory rate"},I19))),"Physiological", ""), IF(OR(ISNUMBER(SEARCH({"genetic"},I19))),"Risk", ""), IF(OR(ISNUMBER(SEARCH({"ultrasound","uv photog","facial","oral","CT scan"},I19))),"Imaging", ""), IF(OR(ISNUMBER(SEARCH({"glucose","hb1ac","lipids","nutrient"},I19))),"Blood", ""),IF(OR(ISNUMBER(SEARCH({"anthropometrics"},I19))),"Anthropometry", ""))} -> Physiological, Blood, Anthropometry | I19: Blood pressure, glucose, lipids, anthropometrics | J19: Triglycerides, high density lipoprotein (HDL), fasting blood glucose, waist circumference, blood pressure. | K19: 4 | L19: RCT | M19: Adults (92 in the intervention group and 88 in the intensive health monitoring group). | N19: 180 | O19: 90 | P19: =(46.94*92+44.58*88)/(92+88) -> 45.786222 | Q19: Yes | R19: Yes | S19: 12 months | T19: The intervention compared outcomes of two voluntary workplace health management methods: an adapted worksite self-management (WSM) approach and an intensive health monitoring (IM) approach. Participants were randomly assigned to either the WSM group or the IM group. WSM participants met weekly in groups of fewer than 12 members for 50 min to review the previous week’s action plan, develop a weekly goal and write an action plan for that goal. Participants could opt-in for group feedback on their action plans, and plans were modified until the participants noted their confidence level in adhering to the plan as at least an 8 on a 10-point scale. Participants also shared challenges, success stories, and health information. Groups were co-facilitated by a project staff member and a trained lay co-leader. The IM intervention consisted of three pre-scheduled biometric screenings and health surveys at baseline, 3 and 12 months. Both groups received adapted CDC health promotion materials on PA, healthy eating, stress reduction, and other primary prevention materials. A Master’s level registered nurse with a background in health promotion provided one-on-one phone counselling to review participants’ biometric results and discuss health promotion materials. | U19: Yes | V19: Self-efficacy was measured via the new general self-efficacy scale (GSE). Health behaviours were measured using the Revised health lifestyle profile II (HPLP-IIR), which measures self-reported frequency of participating in health behaviors (health responsibility, physical activity, nutrition, spiritual growth, interpersonal relations and stress management). Number of days per week on which they engaged in at least 30 mins of PA (any activity that increases heart rate and makes one get out of breath some of the time). Depression symptoms were measured using the Personal health questionnaire (PHQ–8), which contains 8/9 depressive disorder criteria from the DSM-IV. Biomarkers measured included triglycerides, high density lipoprotein (HDL), fasting blood glucose, waist circumference and blood pressure. | W19: Yes | X19: Employees in both groups reported increases in self-efficacy both from baseline to 3 and baseline to 12 months. Likewise, employees in both groups reported improved health behaviors as measured by the HPLP-IIR, in all the subscales except for one. Individuals in the WSM group did not improve in the stress management subscale from baseline to 3 months, but did improve from baseline to 12 months. Individuals in the IM groups improved at both time periods on the stress management subscale. Individuals in the WSM group improved in depression symptoms at both time periods, whereas individuals in the IM group did not improve at either time period. Participants in the WSM group reported improved health and energy levels at 3 and 12 months (all P values < 0.0001). Participants in the IM group reported improved health at 12 months (P = 0.01) and improved energy at 3 and 12 months (P = 0.0037; P = 0.0006). Participants in both groups reported their health interfered less with their personal life and work life at 3 and 12 months, compared to baseline (all P values < 0.001). Both groups also stated experiencing less difficulty with daily activities due to their health at 3 and 12 months (P values 0.0001 to 0.02), compared to baseline. No changes were observed in biometrics in either group from baseline to 3 or 12 months. | Y19: Yes | Z19: In person, telephone | AA19: 2 | AB19: Once | AC19: Self-Efficacy Theory, Social Learning Theory | AD19: Goal directed BCT Social support BCT Advise specific behaviour BCT | AE19: 3 | AF19: BCIO:007019: record behaviour without feedback BCT **NOTE: from BCTO hierarchy sheet The monitoring agent can be a human or a technical device. If recording is part of a data collection procedure rather than a strategy aimed at changing behaviour, do not code; if feedback given, code only 'provide feedback on outcome of behaviour BCT' and not this class; if observing behaviour code 'observe behaviour without feedback BCT'.
A20: Smith, Eric N., Santoro, Erik, Moraveji, Neema, Susi, Michael, Crum, Alia J. | B20: Integrating wearables in stress management interventions: Promising evidence from a randomized trial | C20: 2020 | D20: 10.1037/str0000137 10.1037/str0000137.supp (Supplemental) | E20: Effective | F20: Stress management | G20: 1 | H20: {=_xlfn.TEXTJOIN(", ", TRUE, IF(OR(ISNUMBER(SEARCH({"blood pressure","heart rate","anthropometrics","ecg","vo2max","spirometry","respiratory rate"},I20))),"Physiological", ""), IF(OR(ISNUMBER(SEARCH({"genetic"},I20))),"Risk", ""), IF(OR(ISNUMBER(SEARCH({"ultrasound","uv photog","facial","oral","CT scan"},I20))),"Imaging", ""), IF(OR(ISNUMBER(SEARCH({"glucose","hb1ac","lipids","nutrient"},I20))),"Blood", ""),IF(OR(ISNUMBER(SEARCH({"anthropometrics"},I20))),"Anthropometry", ""))} -> Physiological | I20: Respiratory rate / variability | J20: Pulmonary function | K20: 1 | L20: Randomised intervention (Note: participants had to pay $50 to enrol, which could be redeemed for "wellness" points) | M20: Adults employed at a tech company (102 control; 67 treatment; mean age = 33.2; SD = 7.8). | N20: 169 | O20: 55 | P20: 33.2 | Q20: No | R20: No | S20: 4 weeks | T20: Participants were provided with a "Spire Stone" (a monitor connected to an app which measures monitors respiratory effort and physical activity to assess metrics such as respiratory rate and respiratory rate variability, as well as steps and sedentary periods). The treatment included in-app guided breathing training modules modeled after mindfulness-based stress reduction (MBSR) programs and four wearable-based treatment components: (a) wearing of the device itself, (b) tracking and visualization of past physiological states, (c) visual real-time biofeedback, and (d) real-time notifications on significant and sustained changes of the user’s respiratory patterns. | U20: No | V20: Primary: Stress (measured with percieved stress scale [PSS]), negative symptoms of mental health such as anxiety, depression, and general distress (Mood and Anxiety Symptoms Questionnaire [MASQ]), perceived physical and mental health over time (Center for Disease Control’s Healthy Days Core and Symptoms Modules [CDC HRQOL-14]), and a single-item questionnaire about their own life-stress level. Secondary: Additional components of CDC HRQOL-14 were given to participants, to measure how many days in the past 30 days they (a) felt their mental health was not good, and (b) felt sad, blue, or depressed. Positive and negative emotions (measured via the Positive and Negative Affect Schedule), and enjoyment (measured via the Net-Promoter score). Respiratory data was alo measured. | W20: No | X20: Participants randomly assigned to the treatment group reported 15.8% fewer negative instances of stress, 13.0% fewer distressing symptoms, and 28.2% fewer days feeling anxious or stressed compared with a waitlist control. | Y20: No | Z20: Device/Online | AA20: 1 | AB20: More than once | AC20: None | AD20: Guide how to perform behaviour BCT Advise how to change emotions BCT Monitoring BCT Goal directed BCT | AE20: 4 | AF20: BCT2.4 Self-monitoring of outcome(s) of behaviour
A21: Iwahori, T., Ueshima, H., Ohgami, N., Yamashita, H., Miyagawa, N., Kondo, K., Torii, S., Yoshita, K., Shiga, T., Ohkubo, T., Arima, H., Miura, K. | B21: Effectiveness of a Self-monitoring Device for Urinary Sodium-to-Potassium Ratio on Dietary Improvement in Free-Living Adults: a Randomized Controlled Trial | C21: 2018 | D21: 10.2188/jea.JE20160144 | E21: Not effective | F21: Diet | G21: 1 | H21: {=_xlfn.TEXTJOIN(", ", TRUE, IF(OR(ISNUMBER(SEARCH({"blood pressure","heart rate","anthropometrics","ecg","vo2max","spirometry","respiratory rate"},I21))),"Physiological", ""), IF(OR(ISNUMBER(SEARCH({"genetic"},I21))),"Risk", ""), IF(OR(ISNUMBER(SEARCH({"ultrasound","uv photog","facial","oral","CT scan"},I21))),"Imaging", ""), IF(OR(ISNUMBER(SEARCH({"glucose","hb1ac","lipids","nutrient"},I21))),"Blood", ""),IF(OR(ISNUMBER(SEARCH({"anthropometrics"},I21))),"Anthropometry", ""))} -> Physiological, Blood, Anthropometry | I21: Nutrient biomarkers, anthropometrics, blood pressure | J21: Urinary sodium-to-potassium ratio | K21: 3 | L21: open, prospective, parallel RCT | M21: Adults | N21: 92 | O21: 52.2 | P21: 54.5 | Q21: No | R21: No | S21: 1 month | T21: Eligible study participants were randomly allocated into two groups. All subjects in the “device + usual care” intervention group, but not those in the “usual care” control group, were given portable handy-sized urinary Na/K ratio monitors. Participants in the intervention group were asked to measure at least one spot urine Na/K ratio daily, and to try to reduce their Na and increase their K intake to achieve a target set by investigators. All participants received a brief dietary education that provided details on how to avoid high salt foods and which vegetables and fruits could be consumed in order to increase K intake. For salt reduction, participants were given information on the top 10 Na intake sources in Japanese meals and were then advised on how to avoid these foods by replacing them with other reduced-Na alternatives. To increase the K, participants were provided with information on the major K intake sources that were available in local grocery stores. All parrticipants then received a leaflet that summarised this dietary information prior to the start of trial. | U21: Yes | V21: Primary outcome was the change in 24-hour urinary Na/K ratio (a proxy for confirming reduction in dietary salt intake). Secondary outcomes included changes in the 24-hour excretion of Na and K, BP, and body weight. | W21: No | X21: There was a non-significant trend towards larger reductions in urinary Na/K ratio observed in the intervention group, but effect of the self-monitoring device on the urinary Na/K ratio did not reach the accepted level of statistical significance on the pre-specified effect size. Changes in urinary sodium-to-potassium ratio were −0.55 in the intervention group and −0.06 in the control group (P = 0.088); respective sodium excretion changes were −18.5 mmol=24 hours and −8.7 mmol=24 hours (P = 0.528); and corresponding potassium excretion was 2.6 mmol=24 hours and −1.5 mmol=24 hours (P = 0.300). No significant reductions were observed in either blood pressure or body weight after the intervention. | Y21: No | Z21: Device/Online | AA21: 1 | AB21: More than once | AC21: None | AD21: Guide how to perform behaviour BCT Monitoring BCT | AE21: 2 | AF21: BCT2.4 Self-monitoring of outcome(s) of behaviour
A22: Wengreen, H. J., Nix, E., Madden, G. J. | B22: The effect of social norms messaging regarding skin carotenoid concentrations among college students | C22: 2017 | D22: 10.1016/j.appet.2017.04.027 | E22: Not effective | F22: Diet | G22: 1 | H22: {=_xlfn.TEXTJOIN(", ", TRUE, IF(OR(ISNUMBER(SEARCH({"blood pressure","heart rate","anthropometrics","ecg","vo2max","spirometry","respiratory rate"},I22))),"Physiological", ""), IF(OR(ISNUMBER(SEARCH({"genetic"},I22))),"Risk", ""), IF(OR(ISNUMBER(SEARCH({"ultrasound","uv photog","facial","oral","CT scan"},I22))),"Imaging", ""), IF(OR(ISNUMBER(SEARCH({"glucose","hb1ac","lipids","nutrient"},I22))),"Blood", ""),IF(OR(ISNUMBER(SEARCH({"anthropometrics"},I22))),"Anthropometry", ""))} -> Blood | I22: Nutrient biomarkers | J22: Skin carotenoid concentrations | K22: 1 | L22: randomised intervention | M22: First-year nutrition students (mean age 20, ±3.6 years) | N22: 185 | O22: 69.7 | P22: 20 | Q22: No | R22: No | S22: 7 weeks | T22: Students completed an online assessment of their usual dietary intake of FV over the past month, and were randomly assigned to the Individualized Normative Feedback group (n = 57), Manipulated Normative Feedback group (n = 62), or the Control group (n = 66). Group assignment was not disclosed to participants. As part of the course curriculum, all students were informed about the validity of skin carotenoids as a biomarker of carotenoid-containing FV consumption. Skin carotenoid levels were measured in the second week of the class and all participants were given a printed message that included the sentence, “Eating more vegetables and fruits that are red, orange, yellow, green, or purple will help to increase your skin carotenoid score.” Control group participants were told, “You will receive your skin carotenoid score in approximately 7 weeks.” Participants in the Manipulated Normative group were given a printed message that did not indicate their score, but instead said, “Your skin carotenoid score is in the 20th percentile of skin carotenoid scores for college students attending Utah State University. 80% of college students have a higher skin carotenoid score than you. Students who eat the recommended amount of fruits and vegetables have skin carotenoid scores of 35,000 or higher.” 47 of 62 (76%) students who were randomized to the Manipulated Normative group were deceived by the message communicated to them (i.e., their skin carotenoid level was not in the bottom 20% of scores among college students). Participants in the Individualized Normative group were given a printed message that included their skin carotenoid score, a visual representation of the distribution of scores measured in a reference population of “college students attending Utah State University,” and their percentile ranking within that reference distribution which was obtained from 344 students enrolled in the same course during the previous year (mean = 24,172, SD = 8697; range: 5820–52,050). For example, “Your skin carotenoid score of 32,808 is in the 82%ile of skin carotenoid scores for college students attending Utah State University. 18% of college students have a score that is higher than your score. Students who eat the recommended amount of fruits and vegetables typically have skin carotenoid scores of 35,000 or higher.” | U22: Yes | V22: Skin carotenoid concentrations, F&V consumption (self-reported). | W22: Yes | X22: Skin carotenoid levels of participants in the Manipulated Normative group increased significantly more than those in the Control group (t (126) = 3.74, p < 0.001; d = 0.67), but these students' self-reported FV intake did not increase. | Y22: No | Z22: Written Communication | AA22: 1 | AB22: Once | AC22: Focus Theory of Normative Conduct | AD22: Increase awareness of consequences BCT | AE22: 1
A23: Doets, de Hoogh, Holthuysen, Wopereis, Verain, van den Puttelaar, Hogenelst, Boorsma, Bouwman, Timmer, Pasman, van Erk, Reinders. | B23: Beneficial effect of personalized lifestyle advice compared to generic advice on wellbeing among Dutch seniors: An explorative study | C23: 2019 | D23: 10.1016/j.physbeh.2019.112642 | E23: Not effective | F23: Diet, Physical activity | G23: 2 | H23: {=_xlfn.TEXTJOIN(", ", TRUE, IF(OR(ISNUMBER(SEARCH({"blood pressure","heart rate","anthropometrics","ecg","vo2max","spirometry","respiratory rate"},I23))),"Physiological", ""), IF(OR(ISNUMBER(SEARCH({"genetic"},I23))),"Risk", ""), IF(OR(ISNUMBER(SEARCH({"ultrasound","uv photog","facial","oral","CT scan"},I23))),"Imaging", ""), IF(OR(ISNUMBER(SEARCH({"glucose","hb1ac","lipids","nutrient"},I23))),"Blood", ""),IF(OR(ISNUMBER(SEARCH({"anthropometrics"},I23))),"Anthropometry", ""))} -> Physiological, Risk, Blood, Anthropometry | I23: Blood pressure, anthropometrics, genetics, glucose, Lipids | J23: Blood pressure, body composition, genetics, glucose, lipids, weight/BMI | K23: 5 | L23: single-blind RCT | M23: Sedentary adults (age 67.7 ± 4.8 years). | N23: 59 | O23: 63 | P23: 67.7 | Q23: No | R23: No | S23: 9 weeks | T23: Participants either received personalised advice (PA) or generic advice (GA). Biological measurements were performed at baseline (T = 0) to quantify individual health status to be used in feedback for subjects in both groups (PA+GA) and as input for the decision trees to determine the content of the PA. PA was given based on metabolic health measures and dietary intake resulting in an advice that highlighted food groups and physical activity types for which behavior change was most urgent. | U23: No | V23: Self-perceived health as parameter of wellbeing using a self-perceived health score (single-item) and two questionnaires (Vita-16 and Short Form-12). Anthropometrics and physical functioning (short physical performance battery [SPPB]) were assessed. | W23: No | X23: Overall scores for self-perceived health did not change over time in any group. Resilience and motivation (Vita-16) slightly improved only in the PA group, whilst mental health (SF-12) and energy (Vita-16) showed slight improvement only in the GA group. SPPB scores improved over time in both the PA and GA group. PA participants also showed a reduction in body fat percentage and hip circumference, whereas these parameters increased in the GA group. | Y23: No | Z23: Written Communication | AA23: 1 | AB23: Once | AC23: Self-Efficacy Theory, Social Cognitive Theory | AD23: Monitoring BCT Increase awareness of consequences BCT Social Support | AE23: 3
A24: Kocher, Erica | B24: Evaluating the Feasibility and Effectiveness of Self-Monitoring of Health: a Pilot Study among Samoan Women | C24: 2019 | D24: 10.26635/phd.2020.636 | E24: Not effective | F24: Physical activity | G24: 1 | H24: {=_xlfn.TEXTJOIN(", ", TRUE, IF(OR(ISNUMBER(SEARCH({"blood pressure","heart rate","anthropometrics","ecg","vo2max","spirometry","respiratory rate"},I24))),"Physiological", ""), IF(OR(ISNUMBER(SEARCH({"genetic"},I24))),"Risk", ""), IF(OR(ISNUMBER(SEARCH({"ultrasound","uv photog","facial","oral","CT scan"},I24))),"Imaging", ""), IF(OR(ISNUMBER(SEARCH({"glucose","hb1ac","lipids","nutrient"},I24))),"Blood", ""),IF(OR(ISNUMBER(SEARCH({"anthropometrics"},I24))),"Anthropometry", ""))} -> Physiological, Anthropometry | I24: Anthropometrics | J24: Weight/BMI | K24: 1 | L24: pilot RCT | M24: Samoan women | N24: 44 | O24: 100 | P24: 36.3 | Q24: No | R24: Yes | S24: 4 weeks | T24: Two types of devices were used FitBitZip® activity monitors and BodyTrace© scales. Participants were randomly assigned to one of three groups for a four-week intervention period: 1) FitBit Zip® step-counter, 2) digital BodyTrace© scale, or 3) both devices. All participants wore FitBits for the duration of the intervention period to measure their physical activity; the screens were uncovered for the groups assigned to selfmonitor using the FitBits, but they remained covered in the Scale Only group. Participants then used the devices for a four-week intervention period. The research team visited participants once at approximately the midpoint of the four-week intervention period to download data from the FitBits. This visit did not include any additional surveys or any feedback on the outcomes of interest. | U24: No | V24: The study measured device use, daily step counts, and BMI, in addition to psychosocial indicators of health (assessed via various questionnaires: The Multidimensional Health Locus of Control Scale [HLOC] which measures an individual’s perceived control of their own health [Internal], the influence of random luck [Chance], and the influence of others such as friends, family, and medical providers [Powerful Others]; The Self-efficacy for Exercise Behaviors Scale; the Weight Efficacy Life Style Questionnaire; The SF8 Quality of Life scale; a self reported health question which asked individuals to assess their overall health for their age [Excellent, Very Good, Good, Poor, and Very Poor]. | W24: Yes | X24: There was no effect on PA levels, measured using median daily step counts. A significant increase in BMI between the baseline and post intervention assessments was observed among the two groups that used scales (Scale Only p=0.005, FitBit and Scale p=0.058), while the FitBit Only group had a slight, nonsignificant decrease in BMI (p=0.898). Post intervention the three groups did not differ in their HLOC subscale scores. Median scores on HLOC subscales increased by a statistically significant amount in the Scale Only and the combined FitBit and Scale groups. The FitBit Only group had a significant increase in the ‘Chance’ and ‘Powerful Others’ subscales, but no significant change in the Internal subscale. All three groups significantly increased their Self-efficacy for Exercise post-intervention, with a median increase in score of 16.0 points across all three groups. The FitBit Only and FitBit and Scale groups had a significant increase in Weight Control Self Efficacy following the intervention of 18.0 and 14.0 respectively, while the Scale Only group had a moderately significant increase of 12.0 (p=0.053) There was no significant difference in FibtBit use between the three groups during the baseline assessment or intervention. There was also a significant difference in self-assessed health changed during the intervention period. In the FitBit Only group SF-8 scores increased for both physical (2.5 to 6.5, p=0.002) and mental (3.0 to 6.0, p=0.008) health, indicating worsening quality of life. There were no reported changes in the SF-8 scores of the other two groups. Prior to the intevention, all participants self-reported their health as excellent, very good, or good. However, post-intervention the proportion of individuals in the FitBit only group reporting that their health was excellent increased (from 73.3% to 86.7%), while the proportion decreased for the Scale Only (64.3% to 57.1%) and FitBit and Scale groups (80.0% to 33.3%) (p=0.038). | Y24: No | Z24: Device/Online | AA24: 1 | AB24: More than once | AC24: None | AD24: Monitoring BCT | AE24: 1 | AF24: BCT2.3 Self-monitoring of behaviour
A25: Hollands, G. J., Marteau, T. M. | B25: The impact of using visual images of the body within a personalized health risk assessment: an experimental study | C25: 2013 | D25: 10.1111/bjhp.12016 | E25: Not effective | F25: Physical activity | G25: 1 | H25: {=_xlfn.TEXTJOIN(", ", TRUE, IF(OR(ISNUMBER(SEARCH({"blood pressure","heart rate","anthropometrics","ecg","vo2max","spirometry","respiratory rate"},I25))),"Physiological", ""), IF(OR(ISNUMBER(SEARCH({"genetic"},I25))),"Risk", ""), IF(OR(ISNUMBER(SEARCH({"ultrasound","uv photog","facial","oral","CT scan"},I25))),"Imaging", ""), IF(OR(ISNUMBER(SEARCH({"glucose","hb1ac","lipids","nutrient"},I25))),"Blood", ""),IF(OR(ISNUMBER(SEARCH({"anthropometrics"},I25))),"Anthropometry", ""))} -> Physiological, Anthropometry | I25: Anthropometrics | J25: Body composition, weight/BMI | K25: 1 | L25: experimental study | M25: Adults | N25: 901 | O25: 61.5 | P25: 27.2 | Q25: No | R25: No | S25: 1 month | T25: All participants received an assessment and information focusing on the health implications of internal body fat and highlighting the protective beneﬁts of PA. Participants were randomised to receive this in either (a) solely text form (control arm) or (b) text plus a visual image of predicted internal body fat (image arm). Participants received information representing one of three levels of health threat, determined by how physically active they were: high, moderate or benign. All participants recieved information on the difference between internal (intra-abdominal) and external (subcutaneous) body fat; an explanation of the link between internal fat and cardiovascular risk; and a prediction of the likely range of internal body fat the participant had. Participants in the experimental arm were presented with a visual image (standardised for each level of health risk) of what their body fat distribution might look like, additional to the text. The images used were representative of those likely to be given in feedback in health care settings, consisting of a full-body MRI scan image that was digitally manipulated to alter the visible fat distribution. Participants were informed that their risk assessment was based on a combination of baseline anthropometric and demographic details + their PA questionnaire responses. In reality (as was emphasised inthe debrieﬁng upon completion of the study), the information was based on a measure of current PA. The purpose of this basic tailoring was to provide a broadly plausible risk assessment to the recipient (i.e., ensuring that individuals who were highly physically active received benign risk information) but to retain control of the range ofinformation being communicated. By informing participants that the assessment was complex, it was intended to provide face validity and encourage engagement with the intervention. | U25: No | V25: Primary outcome measure: intention to meet recommended PA levels (assessed using a single item questionnaire). | W25: No | X25: Receipt of a visual image did not increase PA intentions overall [F(1,898) = 3.47, p = .063, r = .06]. The image intervention did signiﬁcantly increase intentions in participants who received a high level of communicated risk,(F(1,471) = 4.45, p = .035, r = .10), with no effect on those who received moderate or benign levels of communicated risk (p values > .10). The interaction between image intervention and level of communicated risk was not signiﬁcant, F(5,895) = 1.323,p = >.10. | Y25: No | Z25: Written Communication | AA25: 1 | AB25: Once | AC25: Common Sense Model, Protection Motivation Theory, Theory of Planned Behavior | AD25: Increase awareness of consequences BCT | AE25: 1
